//using promise.
// const asyncHandler = (requestHandler) => {
//   (req, res, next) => {
//     Promise.resolve(requestHandler(req, res, next)).catch((err) => next(err));
//   };
// };

//using try catch block
const asyncHandler = (fn) => async (req, res, next) => {
  try {
    await fn(req, res, next);
  } catch (error) {
    res.status(error.code || 500).json({
      success: false,
      message: `Error in utils folder ${error}`,
    });
  }
};
export { asyncHandler };
